/**
 * in the javascript we will learn about the errors 
 * 
 * Throw and Try Catch Finally 
 */
try{
    allll("hello")
}
catch(error){
    console.log("hello")  //alllll is not defined 
}

/**
 * we have the the throw in the javascript 
 */
// throw "hello";


/**
 * finally statment in the javascript 
 * finally block will run even when the exceptions is not raised and even also when the excpestions is raised 
 */
try{
    console.log("hello");
}
catch(error){
    console.log("catch is running")
}
finally{
    console.log("finally block is running")
}

